Workbook

Sheet DADOS APLICAÇÃO CALCULO
B2: DADOS DA CONTRATAÇÃO BANCARIA
B3: NOME DO CLIENTE | F3: NOME DO CLIENTE
B4: NUMERO DO CONTRATO
B5: DATA DA CONTRATAÇÃO | F5: 45148
B6: TIPO DA CONTRATAÇÃO | F6: PRESENCIAL
B7: FORMA DE ASSINATURA | F7: FISICA
B8: TIPO DE CONTRATO
B9: TIPO | F9: CONSIGNADO
B10: DATA DA CONTRATAÇÃO | I10: 45148
B11: VALOR CONTRATADO OU REFINANCIADO | I11: 39318.44
B12: TROCO | I12: 6000
B13: SEGURO PRESTAISTA | J13: =SUM(I11:I12) -> 45318.44
B14: IOF | I14: 206.13
B15: TAXA ABERTURA
B16: TAXA REGISTRO
B18: TOTAL CONTRATADO | I18: =SUM(I11:I17) -> 45524.57
B19: TOTAL DE PARCELAS | I19: 72
B20: VALOR DA PARCELA A SER DESCONTADA | I20: 1221.35
B21: VALOR DA TAXA DE JUROS PACTUADA | I21: 0.0197
B22: DATA DO PAGAMENTO DA PRIMEIRA PARCELA | I22: 45208
B23: TAXA DE JUROS PRATICADAS OU COBRADA | I23: 0.020851286
B24: VALOR DA PARCELA PELA TAXA PACTUADA | I24: 1183.2065
B25: VALOR DA DIFERENÇA ENTRE TAXA CONTRATA E COBRADA
B26: VALOR DA DIFERENÇA ENTRE CONTRATA E COBRADA
B27: TOTAL DE PARCELA PAGAS ATE A PRESENTE DATA | I27: 36
B28: QUITAÇÃO COM APLICAÇÃO DA TAXA CONTRATUAL | I28: 67
B29: VALOR PAGO ATÉ A PRESENTE DATA | I29: =I27*I20 -> 43968.6
B30: SALDO A PAGAR
B31: VALOR PAGO INDEVIDAMENTE
B32: DATA DA EXCLUSÃO
B33: INDICE ACIMA DA TAXA CONTRATUAL | I33: 0.20121951 | J33: 0
B37: DADOS PARA CALULO COM A TAXA MÉDIA
B38: VALOR DA TAXA MEDIA BANCO CENTRAL | I38: 0.0164
B39: VALOR DA PARCELA MENSAL PELA TAXA MEDIA | I39: 1077.115
B40: DIFERENÇA ENTRE A TAXA COBRADA E TAXA MEDIA
B41: INDICE ACIMA DA TAXA MEDIA
B42: QUITAÇÃO DA DIVIDA PELA TAXA MEDIA NA PARCELA? | I42: 58
B43: TOTAL DA DIVIDA PELA TAXA MEDIA
B44: VALOR PAGO INDEVIDAMENTE
B47: DADOS PARA CALCULO COM A IN 28
...

Sheet CALCULO DE DATAS
B2: TOTAL DE PARCELA PAGAS ATE FIM DO CONTRATO | H2: TOTAL DE PARCELA PAGAS ATE PRESENTE DATA
B3: 1º CONTRATO | C3: INICIO CONTRATO | E3: FIM CONTRATO | H3: 1º CONTRATO | I3: INICIO CONTRATO | K3: MÊS ATUAL
C4: ='DADOS APLICAÇÃO CALCULO'!F5 -> 45148 | E4: 46122 | I4: =C4 -> 45148 | K4: 46264
C5: ANO | D5: MÊS | E5: DIA | I5: ANO | J5: MÊS | K5: DIA
C6: =DATEDIF(C4,E4,"Y") -> 2 | D6: =DATEDIF(C4,E4,"YM") -> 8 | E6: =DATEDIF(C4,E4,"MD") -> 0 | I6: =DATEDIF(I4,K4,"Y") -> 3 | J6: =DATEDIF(I4,K4,"YM") -> 0 | K6: =DATEDIF(I4,K4,"MD") -> 20
D7: TOTAL MESES | J7: TOTAL MESES
D8: =(C6*12)+D6 -> 32 | J8: =(I6*12)+J6 -> 36
B9: 2º CONTRATO | C9: TOTAL DE PARCELAS | F9: 72
C10: AGREGAR DIAS VER DATA FINAL
C11: DATA INICIAL | E11: DATA FINAL
C12: =C4 -> 45148 | E12: =EDATE(C12,F9) -> 47340
B15: CALCULO DE DATA PARA EXCLUSÃO
B16: TOTAL DE PARCELAS PAGAS
B17: 3º CONTRATO | C17: INICIO CONTRATO | E17: DATA DA EXCLUSÃO
C18: =C4 -> 45148 | E18: 46122
C19: ANO | D19: MÊS | E19: DIA
C20: =DATEDIF(C18,E18,"Y") -> 2 | D20: =DATEDIF(C18,E18,"YM") -> 8 | E20: =DATEDIF(C18,E18,"MD") -> 0
D21: TOTAL MESES
D22: =(C20*12)+D20 -> 32

Sheet TAXA MEDIA 
B2: HISTORICO DA TAXA DE JUROS
B3: Seguimento: | D3: Pessoa Fisica
B4: Período: | D4: 45148 | E4: a | F4: 42387
B5: Modalidade: | D5: Credito pessoal consignado INSS - Pre-Fixado
B6: POSIÇÃO | C6: CNPJ | D6: INSTITUÇÃO FINANCEIRO | E6: % A.M | F6: % A.A.
B8: 1 | C8: 2038232 | D8: BANCO SICOOB S.A. | E8: 1.4 | F8: 18.17
B9: 2 | C9: 17167412 | D9: FINANCEIRA ALFA S.A. - SCFI | E9: 1.48 | F9: 19.28
B10: 3 | C10: 33136888 | D10: BRB - CFI S/A | E10: 1.5 | F10: 19.56
B11: 4 | C11: 92702067 | D11: BCO DO ESTADO DO RS S.A. | E11: 1.51 | F11: 19.67
B12: 5 | C12: 416968 | D12: BANCO INTER | E12: 1.52 | F12: 19.79
B13: 6 | C13: 1181521 | D13: BANCO COOPERATIVO SICREDI | E13: 1.53 | F13: 19.92
B14: 7 | C14: 4902979 | D14: BCO DA AMAZONIA S.A. | E14: 1.56 | F14: 20.44
B15: 8 | C15: 360305 | D15: CAIXA ECONOMICA FEDERAL | E15: 1.61 | F15: 21.09
B16: 9 | C16: 3311443 | D16: MEUTUDO SCFI | E16: 1.63 | F16: 21.42
B17: 10 | C17: 62232889 | D17: BCO DAYCOVAL S.A | E17: 1.71 | F17: 22.51
B18: 11 | C18: 11760553 | D18: GAZINCRED S.A. SCFI | E18: 1.74 | F18: 23.01
B19: 12 | C19: 0 | D19: BCO DO BRASIL S.A. | E19: 1.83 | F19: 24.26
... B44: 37 | C44: 33040601 | D44: MERCANTIL FINANCEIRA | E44: 2.17 | F44: 29.41
E45: =SUM(E8:E12)/5 -> 1.482
E46: 0.0148

Sheet TODOS 6 CALCULOS
B2: TAXA COBRADA DO CLIENTE
B4: FINANCIAMENTO COM PARCELAS FIXAS
B5: Número de meses | D5: ='DADOS APLICAÇÃO CALCULO'!I19 -> 72
B6: Taxa de Juros Praticada | D6: =RATE(D5,-D7,D8) -> 0.020851286 | I6: 0
B7: Valor da Prestação | D7: ='DADOS APLICAÇÃO CALCULO'!I20 -> 1221.35
B8: Valor Financiado | D8: ='DADOS APLICAÇÃO CALCULO'!J13 -> 45318.44
B10: TAXA DO CONTRATO REDUZ A PARCELA | F10: V. COBRADO
B11: FINANCIAMENTO COM PARCELAS FIXAS | F11: =D7 -> 1221.35
B12: Número de meses | D12: ='DADOS APLICAÇÃO CALCULO'!I19 -> 72 | F12: TX CONTRAT
B13: Taxa de Juro de Juros Contrato | D13: ='DADOS APLICAÇÃO CALCULO'!I21 -> 0.0197 | F13: =D14 -> 1183.2065
B14: Valor da Prestação | D14: =-PMT(D13,D12,D15) -> 1183.2065 | F14: DIFERENÇA
B15: Valor Financiado | D15: ='DADOS APLICAÇÃO CALCULO'!J13 -> 45318.44 | F15: =F11-F13 -> 38.143456
B17: TAXA DO CONTRATO REDUZ O PRAZO
B18: FINANCIAMENTO COM PARCELAS FIXAS
B19: Número de meses | D19: =ROUND(NPER(D20,D21,-D22),0) -> 67
B20: Taxa de Juro de Juros Contrato | D20: ='DADOS APLICAÇÃO CALCULO'!I21 -> 0.0197
B21: Valor da Prestação | D21: ='DADOS APLICAÇÃO CALCULO'!I20 -> 1221.35
B22: Valor Financiado | D22: ='DADOS APLICAÇÃO CALCULO'!J13 -> 45318.44
B24: TAXA IN 28 REDUZ O PRAZO
B25: FINANCIAMENTO COM PARCELAS FIXAS
B26: Número de meses | D26: =ROUND(NPER(D27,D28,-D29),0) -> 62
B27: Taxa de Juros Mensal IN 28 INSS | D27: 0.018 | E27: 0
B28: Valor da Prestação | D28: ='DADOS APLICAÇÃO CALCULO'!I20 -> 1221.35
B29: Valor Financiado | D29: ='DADOS APLICAÇÃO CALCULO'!J13 -> 45318.44
F30: V. COBRADO
B31: TAXA DA IN 28 REDUZ A PARCELA | F31: =D7 -> 1221.35
B32: FINANCIAMENTO COM PARCELAS FIXAS | F32: TX CONTRAT
B33: Número de meses | D33: ='DADOS APLICAÇÃO CALCULO'!I19 -> 72 | F33: =D35 -> 1127.9418
B34: Taxa de Juros Mensal IN 28 INSS | D34: 0.018 | E34: 0 | F34: DIFERENÇA
B35: Valor da Prestação | D35: =-PMT(D34,D33,D36) -> 1127.9418 | F35: =F31-F33 -> 93.408167
B36: Valor Financiado | D36: ='DADOS APLICAÇÃO CALCULO'!J13 -> 45318.44
B39: TAXA MEDIA DE MERCADO - REDUZ O PRAZO
B40: FINANCIAMENTO COM PARCELAS FIXAS
B41: Número de meses | D41: =ROUND(NPER(D42,D43,-D44),0) -> 58
B42: Taxa de Juros Mensal | D42: ='DADOS APLICAÇÃO CALCULO'!I38 -> 0.0164
B43: Valor da Prestação | D43: ='DADOS APLICAÇÃO CALCULO'!I20 -> 1221.35
B44: Valor Financiado | D44: ='DADOS APLICAÇÃO CALCULO'!J13 -> 45318.44
B46: TAXA MEDIA DE MERCADO - REDUZ O VALOR DA PARCELA | F46: V. COBRADO
B47: FINANCIAMENTO COM PARCELAS FIXAS | F47: =D43 -> 1221.35
B48: Número de meses | D48: ='DADOS APLICAÇÃO CALCULO'!I19 -> 72 | F48: TX CONTRAT
...

Sheet 1.1 QUITACAO PARCIAL TAXA MEDIA
B2: HISTORICO DO CONTRATO
B3: CONTRATO NUMERO: | D3: {=#REF!} -> #REF!
B4: DATA ASSIANTURA | C4: TAXA CONTRATUAL | D4: TAXA MEDIA MERCADO | E4: TAXA JUROS PRATICADAS | F4: QUITADO NA PARCELA
B5: {='DADOS APLICAÇÃO CALCULO'!F5:G5} -> #VALUE! | C5: ='DADOS APLICAÇÃO CALCULO'!I21 -> 0.0197 | D5: ='DADOS APLICAÇÃO CALCULO'!I38 -> 0.0164 | E5: ='DADOS APLICAÇÃO CALCULO'!I23 -> 0.020851286 | F5: 0
B6: 1ª PARCELA | C6: TOTAL PARCELAS CONTRATADAS | D6: VAL. PARCELA CONTRATUAL | E6: VALOR PARCELA TAXA MEDIA | F6: TOTAL PARCELAS PAGAS
B7: ='DADOS APLICAÇÃO CALCULO'!I22 -> 45208 | C7: ='DADOS APLICAÇÃO CALCULO'!I19 -> 72 | D7: ='DADOS APLICAÇÃO CALCULO'!I20 -> 1221.35 | E7: ='DADOS APLICAÇÃO CALCULO'!I39 -> 1077.115 | F7: ='DADOS APLICAÇÃO CALCULO'!I27 -> 36
B8: PARCELAS: | C8: MESES | D8: VALOR DA PARCELA | E8: VALOR PELA TAXA MEDIA | F8: DIFERENÇA
B9: 1 | C9: 45208 | D9: 1221.35 | E9: 1071.12 | F9: =D9-E9 -> 150.23
B10: 2 | C10: 45239 | D10: 1221.35 | E10: 1071.12 | F10: =D10-E10 -> 150.23
B11: 3 | C11: 45269 | D11: 1221.35 | E11: 1071.12 | F11: =D11-E11 -> 150.23
B12: 4 | C12: 45300 | D12: 1221.35 | E12: 1071.12 | F12: =D12-E12 -> 150.23
B13: 5 | C13: 45331 | D13: 1221.35 | E13: 1071.12 | F13: =D13-E13 -> 150.23
B14: 6 | C14: 45360 | D14: 1221.35 | E14: 1071.12 | F14: =D14-E14 -> 150.23
B15: 7 | C15: 45391 | D15: 1221.35 | E15: 1071.12 | F15: =D15-E15 -> 150.23
B16: 8 | C16: 45421 | D16: 1221.35 | E16: 1071.12 | F16: =D16-E16 -> 150.23
B17: 9 | C17: 45452 | D17: 1221.35 | E17: 1071.12 | F17: =D17-E17 -> 150.23
B18: 10 | C18: 45482 | D18: 1221.35 | E18: 1071.12 | F18: =D18-E18 -> 150.23
B19: 11 | C19: 45513 | D19: 1221.35 | E19: 1071.12 | F19: =D19-E19 -> 150.23
B20: 12 | C20: 45544 | D20: 1221.35 | E20: 1071.12 | F20: =D20-E20 -> 150.23
... B63: 55 | C63: 46852 | D63: 1221.35 | E63: 1071.12 | F63: =D63-E63 -> 150.23
D64: TOTAL DO INDEBITO | F64: =SUM(F9:F63) -> 8262.65
D65: TOTAL DO INDEBITO EM DOBRO | F65: =F64*2 -> 16525.3
B66: 58 | C66: 46882 | D66: 1221.35 | E66: 1071.12
B67: 59 | C67: 45814 | D67: 1221.35 | E67: 1071.12
B68: 60 | C68: 44746 | D68: 1221.35 | E68: 1071.12
B69: 61 | C69: 43678 | D69: 1221.35 | E69: 1071.12
B70: 62 | C70: 42610 | D70: 1221.35 | E70: 1071.12
B71: 63 | C71: 41542 | D71: 1221.35 | E71: 1071.12
B72: 64 | C72: 40474 | D72: 1221.35 | E72: 1071.12
B73: 65 | C73: 39406 | D73: 1221.35 | E73: 1071.12
B74: 66 | C74: 38338 | D74: 1221.35 | E74: 1071.12
B75: 67 | C75: 37270 | D75: 1221.35 | E75: 1071.12
B76: 68 | C76: 36202 | D76: 1221.35 | E76: 1071.12
B77: 69 | C77: 35134 | D77: 1221.35 | E77: 1071.12
... B90: 82 | C90: 21250 | D90: 1221.35 | E90: 1071.12
B91: TOTAL DEVIDO TAXA DO CONTRATO | D91: =SUM(D66:D90) -> 30533.75
B92: TOTAL DEVIDO PELA TAXA MEDIA | E92: =SUM(E66:E91) -> 26778
C93: TOTAL DA ECONOMIA | E93: =D91-E92 -> 3755.75 | F93: =F65+E93 -> 20281.05

Sheet 1.1. INDICE ACIMA TAXA MEDIA
B2: TAXA DE JUROS
B3: Taxa Media de Mercado | C3: ='DADOS APLICAÇÃO CALCULO'!I38 -> 0.0164
B4: Taxa Cobrada pelo Banco | C4: ='DADOS APLICAÇÃO CALCULO'!I23 -> 0.020851286
B5: Porcentagem Acima da Taxa Media Mercado | C5: =((C4-C3)/C3) -> 0.27141989
B61: Porcentagem Acima da Taxa Média | C61: =C5 -> 0.27141989
C62: =1-C61 -> 0.72858011

Sheet 2.2 QUITAÇÃO PARCIAL TAX IN 28
B2: HISTORICO DO CONTRATO
B3: CONTRATO NUMERO: | D3: {=#REF!} -> #REF!
B4: DATA ASSIANTURA | C4: TAXA CONTRATUAL | D4: TAXA MEDIA DA IN 28 INSS | E4: TAXA JUROS PRATICADAS | F4: QUITADO NA PARCELA
B5: {='DADOS APLICAÇÃO CALCULO'!F5:G5} -> #VALUE! | C5: ='DADOS APLICAÇÃO CALCULO'!I21 -> 0.0197 | D5: ='DADOS APLICAÇÃO CALCULO'!I48 -> 0.0197 | E5: ='DADOS APLICAÇÃO CALCULO'!I23 -> 0.020851286 | F5: 0
B6: 1ª PARCELA | C6: TOTAL PARCELAS CONTRATADAS | D6: VAL. PARCELA CONTRATUAL | E6: VALOR PARCELA TAXA IN 28 | F6: TOTAL PARCELAS PAGAS
B7: ='DADOS APLICAÇÃO CALCULO'!I22 -> 45208 | C7: ='DADOS APLICAÇÃO CALCULO'!I19 -> 72 | D7: ='DADOS APLICAÇÃO CALCULO'!I20 -> 1221.35 | E7: ='DADOS APLICAÇÃO CALCULO'!I39 -> 1077.115 | F7: ='DADOS APLICAÇÃO CALCULO'!I27 -> 36
B8: PARCELAS: | C8: MESES | D8: VALOR DA PARCELA | E8: VALOR PELA TAXA MEDIA | F8: DIFERENÇA
B9: 1 | C9: 45208 | D9: 1221.35 | E9: 1077.12 | F9: =D9-E9 -> 144.23
B10: 2 | C10: 45239 | D10: 1221.35 | E10: 1077.12 | F10: =D10-E10 -> 144.23
B11: 3 | C11: 45269 | D11: 1221.35 | E11: 1077.12 | F11: =D11-E11 -> 144.23
B12: 4 | C12: 45300 | D12: 1221.35 | E12: 1077.12 | F12: =D12-E12 -> 144.23
B13: 5 | C13: 45331 | D13: 1221.35 | E13: 1077.12 | F13: =D13-E13 -> 144.23
B14: 6 | C14: 45360 | D14: 1221.35 | E14: 1077.12 | F14: =D14-E14 -> 144.23
B15: 7 | C15: 45391 | D15: 1221.35 | E15: 1077.12 | F15: =D15-E15 -> 144.23
B16: 8 | C16: 45421 | D16: 1221.35 | E16: 1077.12 | F16: =D16-E16 -> 144.23
B17: 9 | C17: 45452 | D17: 1221.35 | E17: 1077.12 | F17: =D17-E17 -> 144.23
B18: 10 | C18: 45482 | D18: 1221.35 | E18: 1077.12 | F18: =D18-E18 -> 144.23
B19: 11 | C19: 45513 | D19: 1221.35 | E19: 1077.12 | F19: =D19-E19 -> 144.23
B20: 12 | C20: 45544 | D20: 1221.35 | E20: 1077.12 | F20: =D20-E20 -> 144.23
... B44: 36 | C44: 46274 | D44: 1221.35 | E44: 1077.12 | F44: =D44-E44 -> 144.23
D45: TOTAL DO INDEBITO | F45: =SUM(F9:F44) -> 5192.28
D46: TOTAL DO INDEBITO EM DOBRO | F46: =F45*2 -> 10384.56
B47: 37 | C47: 46304 | D47: 1221.35 | E47: 1077.12
B48: 38 | C48: 46335 | D48: 1221.35 | E48: 1077.12
B49: 39 | C49: 46365 | D49: 1221.35 | E49: 1077.12
B50: 40 | C50: 46396 | D50: 1221.35 | E50: 1077.12
B51: 41 | C51: 46427 | D51: 1221.35 | E51: 1077.12
B52: 42 | C52: 46455 | D52: 1221.35 | E52: 1077.12
B53: 43 | C53: 46486 | D53: 1221.35 | E53: 1077.12
B54: 44 | C54: 46516 | D54: 1221.35 | E54: 1077.12
B55: 45 | C55: 46547 | D55: 1221.35 | E55: 1077.12
B56: 46 | C56: 46577 | D56: 1221.35 | E56: 1077.12
B57: 47 | C57: 46608 | D57: 1221.35 | E57: 1077.12
B58: 48 | C58: 46639 | D58: 1221.35 | E58: 1077.12
... B90: 82 | C90: 47612 | D90: 1221.35 | E90: 1077.12
B91: TOTAL DEVIDO TAXA DO CONTRATO | D91: =SUM(D66:D90) -> 30533.75
B92: TOTAL DEVIDO PELA TAXA MEDIA | E92: =SUM(E66:E91) -> 26928
C93: TOTAL DA ECONOMIA | E93: =D91-E92 -> 3605.75 | F93: =E93+F46 -> 13990.31

Sheet 2.2 INDICE ACIMA DA TAXA IN 28
B2: TAXA DE JUROS
B3: Taxa da Instrução Normativa 28 do INSS | C3: 0.018
B4: Taxa Cobrada pelo Banco | C4: =#REF! -> #REF!
B5: Porcentagem Acima da Taa da IN 28 | C5: =((C4-C3)/C3) -> #REF!
B61: Porcentagem Acima da Taxa Média | C61: =C5 -> #REF!
C62: =1-C61 -> #REF!

Sheet 3.3 QUITAÇÃO TAXA CONTRATUAL
B2: HISTORICO DO CONTRATO
B3: CONTRATO NUMERO: | D3: =#REF! -> #REF!
B4: DATA ASSIANTURA | C4: TAXA CONTRATUAL | D4: TAXA MEDIA MERCADO | E4: TAXA JUROS PRATICADAS | F4: QUITADO NA PARCELA
B5: ='DADOS APLICAÇÃO CALCULO'!F5 -> 45148 | C5: ='DADOS APLICAÇÃO CALCULO'!I21 -> 0.0197 | D5: ='DADOS APLICAÇÃO CALCULO'!I38 -> 0.0164 | E5: =#REF! -> #REF! | F5: 0
B6: 1ª PARCELA | C6: TOTAL PARCELAS CONTRATADAS | D6: VAL. PARCELA CONTRATUAL | E6: VALOR PARCELA TAXA CONTRATUAL | F6: TOTAL PARCELAS PAGAS
B7: ='DADOS APLICAÇÃO CALCULO'!I22 -> 45208 | C7: ='DADOS APLICAÇÃO CALCULO'!I19 -> 72 | D7: ='DADOS APLICAÇÃO CALCULO'!I20 -> 1221.35 | E7: ='DADOS APLICAÇÃO CALCULO'!I24 -> 1183.2065 | F7: ='DADOS APLICAÇÃO CALCULO'!I27 -> 36
B8: PARCELAS: | C8: MESES | D8: VALOR DA PARCELA | E8: VALOR PELA TAXA MEDIA | F8: DIFERENÇA
B9: 1 | C9: 45208 | D9: 1221.35 | E9: 1183.21 | F9: =D9-E9 -> 38.14
B10: 2 | C10: 45239 | D10: 1221.35 | E10: 1183.21 | F10: =D10-E10 -> 38.14
B11: 3 | C11: 45269 | D11: 1221.35 | E11: 1183.21 | F11: =D11-E11 -> 38.14
B12: 4 | C12: 45300 | D12: 1221.35 | E12: 1183.21 | F12: =D12-E12 -> 38.14
B13: 5 | C13: 45331 | D13: 1221.35 | E13: 1183.21 | F13: =D13-E13 -> 38.14
B14: 6 | C14: 45360 | D14: 1221.35 | E14: 1183.21 | F14: =D14-E14 -> 38.14
B15: 7 | C15: 45391 | D15: 1221.35 | E15: 1183.21 | F15: =D15-E15 -> 38.14
B16: 8 | C16: 45421 | D16: 1221.35 | E16: 1183.21 | F16: =D16-E16 -> 38.14
B17: 9 | C17: 45452 | D17: 1221.35 | E17: 1183.21 | F17: =D17-E17 -> 38.14
B18: 10 | C18: 45482 | D18: 1221.35 | E18: 1183.21 | F18: =D18-E18 -> 38.14
B19: 11 | C19: 45513 | D19: 1221.35 | E19: 1183.21 | F19: =D19-E19 -> 38.14
B20: 12 | C20: 45544 | D20: 1221.35 | E20: 1183.21 | F20: =D20-E20 -> 38.14
... B44: 36 | C44: 46274 | D44: 1221.35 | E44: 1183.21 | F44: =D44-E44 -> 38.14
D45: TOTAL DO INDEBITO | F45: =SUM(F9:F44) -> 1373.04
D46: TOTAL DO INDEBITO EM DOBRO | F46: =F45*2 -> 2746.08
B47: 36 | C47: 46304 | D47: 1221.35 | E47: 1183.21
B48: 37 | C48: 46335 | D48: 1221.35 | E48: 1183.21
B49: 38 | C49: 46365 | D49: 1221.35 | E49: 1183.21
B50: 39 | C50: 46396 | D50: 1221.35 | E50: 1183.21
B51: 40 | C51: 46427 | D51: 1221.35 | E51: 1183.21
B52: 41 | C52: 46455 | D52: 1221.35 | E52: 1183.21
B53: 42 | C53: 46486 | D53: 1221.35 | E53: 1183.21
B54: 43 | C54: 46516 | D54: 1221.35 | E54: 1183.21
B55: 44 | C55: 46547 | D55: 1221.35 | E55: 1183.21
B56: 45 | C56: 46577 | D56: 1221.35 | E56: 1183.21
B57: 46 | C57: 46608 | D57: 1221.35 | E57: 1183.21
B58: 47 | C58: 46639 | D58: 1221.35 | E58: 1183.21
... B83: 72 | C83: 47400 | D83: 1221.35 | E83: 1183.21
B84: TOTAL DEVIDO TAXA DO CONTRATO | D84: =SUM(D47:D83) -> 45189.95
B85: TOTAL DEVIDO PELA TAXA MEDIA | E85: =SUM(E47:E84) -> 43778.77
C86: TOTAL DA ECONOMIA | E86: =D84-E85 -> 1411.18 | F86: =E86+F46 -> 4157.26

Sheet 3.3 INDICE ACIMA TAXA CONTRATUA
B2: TAXA DE JUROS
B3: Taxa Contratual | C3: ='DADOS APLICAÇÃO CALCULO'!I21 -> 0.0197
B4: Taxa Cobrada pelo Banco | C4: ='DADOS APLICAÇÃO CALCULO'!I23 -> 0.020851286
B5: Porcentagem Acima da Taxa Pactuada | C5: =((C4-C3)/C3) -> 0.058440923
B61: Porcentagem Acima da Taxa Média | C61: =C5 -> 0.058440923
C62: =1-C61 -> 0.94155908
