Workbook

Sheet DADOS PARA PETIÇÃO INICIAL
B2: DADOS DA CONTRATAÇÃO BANCARIA
B3: NOME DO CLIENTE | F3: NOME DO CLIENTE
B4: NOME DO BANCO | F4: BANCO ITAU
B5: NUMERO DO CONTRATO
B6: DATA DA CONTRATAÇÃO | F6: 45148
B7: TIPO DA CONTRATAÇÃO | F7: PRESENCIAL
B8: FORMA DE ASSINATURA | F8: FISICA
B9: TIPO DE CONTRATO
B10: TIPO | F10: CONSIGNADO
B11: DATA DA CONTRATAÇÃO | I11: 45148
B12: VALOR CONTRATADO OU REFINANCIADO | I12: 39318.44
B13: TROCO | I13: 6000
B14: SEGURO PRESTAISTA | J14: =SUM(I12:I13) -> 45318.44
B15: IOF | I15: 206.13
B16: TAXA ABERTURA
B17: TAXA REGISTRO
B19: TOTAL CONTRATADO | I19: =SUM(I12:I18) -> 45524.57
B20: TOTAL DE PARCELAS | I20: 72
B21: VALOR DA PARCELA A SER DESCONTADA | I21: 1221.35
B22: VALOR DA TAXA DE JUROS PACTUADA | I22: 0.0197
B23: DATA DO PAGAMENTO DA PRIMEIRA PARCELA | I23: 45208
B24: TAXA DE JUROS PRATICADAS OU COBRADA | I24: ='TODOS 6 CALCULOS'!D6 -> 0.020851286
B25: VALOR DA PARCELA PELA TAXA PACTUADA | I25: ='TODOS 6 CALCULOS'!D14 -> 1183.2065
B26: VALOR DA DIFERENÇA ENTRE TAXA CONTRATA E COBRADA
B27: VALOR DA DIFERENÇA ENTRE CONTRATA E COBRADA
B28: TOTAL DE PARCELA PAGAS ATE A PRESENTE DATA | I28: ='CALCULO DE DATAS'!D6 -> 36
B29: QUITAÇÃO COM APLICAÇÃO DA TAXA CONTRATUAL | I29: ='TODOS 6 CALCULOS'!$D$19 -> 67
B30: VALOR PAGO ATÉ A PRESENTE DATA | I30: =I28*I21 -> 43968.6
B31: SALDO A PAGAR
B32: VALOR PAGO INDEVIDAMENTE
B33: DATA DA EXCLUSÃO
B34: INDICE ACIMA DA TAXA CONTRATUAL | I34: {='1.1.1 PERCENTUAL TAXA MEDIA'!C5:D5} -> 0.20121951 | J34: 0
B38: DADOS PARA CALULO COM A TAXA MÉDIA
B39: VALOR DA TAXA MEDIA BANCO CENTRAL | I39: ='INDICES BACARIOS APURAR TX MEDI'!F44 -> 0.0164
B40: VALOR DA PARCELA MENSAL PELA TAXA MEDIA | I40: ='TODOS 6 CALCULOS'!D50 -> 1077.115
B41: DIFERENÇA ENTRE A TAXA COBRADA E TAXA MEDIA
B42: INDICE ACIMA DA TAXA MEDIA
B43: QUITAÇÃO DA DIVIDA PELA TAXA MEDIA NA PARCELA? | I43: ='TODOS 6 CALCULOS'!D41 -> 58
B44: TOTAL DA DIVIDA PELA TAXA MEDIA
B45: VALOR PAGO INDEVIDAMENTE
...

Sheet CALCULO DE DATAS
B1: 1º CONTRATO | C1: INICIO CONTRATO | E1: FIM CONTRATO
C2: ='DADOS PARA PETIÇÃO INICIAL'!I11 -> 45148 | E2: 46264
C3: ANO | D3: MÊS | E3: DIA
C4: =DATEDIF(C2,E2,"Y") -> 3 | D4: =DATEDIF(C2,E2,"YM") -> 0 | E4: =DATEDIF(C2,E2,"MD") -> 20
D5: TOTAL MESES
D6: =(C4*12)+D4 -> 36
B7: 2º CONTRATO | C7: TOTAL DE PARCELAS | F7: 72
C8: AGREGAR DIAS VER DATA FINAL
C9: DATA INICIAL | E9: DATA FINAL
C10: 45148 | E10: =EDATE(C10,F7) -> 47340

Sheet TODOS 6 CALCULOS
B2: TAXA COBRADA DO CLIENTE
B4: FINANCIAMENTO COM PARCELAS FIXAS
B5: Número de meses | D5: ='DADOS PARA PETIÇÃO INICIAL'!I20 -> 72
B6: Taxa de Juros Praticada | D6: =RATE(D5,-D7,D8) -> 0.020851286 | I6: 0
B7: Valor da Prestação | D7: ='DADOS PARA PETIÇÃO INICIAL'!I21 -> 1221.35
B8: Valor Financiado | D8: ='DADOS PARA PETIÇÃO INICIAL'!J14 -> 45318.44
B10: TAXA DO CONTRATO REDUZ A PARCELA | F10: V. COBRADO
B11: FINANCIAMENTO COM PARCELAS FIXAS | F11: =D7 -> 1221.35
B12: Número de meses | D12: ='DADOS PARA PETIÇÃO INICIAL'!I20 -> 72 | F12: TX CONTRAT
B13: Taxa de Juro de Juros Contrato | D13: ='DADOS PARA PETIÇÃO INICIAL'!I22 -> 0.0197 | F13: =D14 -> 1183.2065
B14: Valor da Prestação | D14: =-PMT(D13,D12,D15) -> 1183.2065 | F14: DIFERENÇA
B15: Valor Financiado | D15: ='DADOS PARA PETIÇÃO INICIAL'!J14 -> 45318.44 | F15: =F11-F13 -> 38.143456
B17: TAXA DO CONTRATO REDUZ O PRAZO
B18: FINANCIAMENTO COM PARCELAS FIXAS
B19: Número de meses | D19: =ROUND(NPER(D20,D21,-D22),0) -> 67
B20: Taxa de Juro de Juros Contrato | D20: ='DADOS PARA PETIÇÃO INICIAL'!I22 -> 0.0197
B21: Valor da Prestação | D21: ='DADOS PARA PETIÇÃO INICIAL'!I21 -> 1221.35
B22: Valor Financiado | D22: ='DADOS PARA PETIÇÃO INICIAL'!J14 -> 45318.44
B24: TAXA IN 28 REDUZ O PRAZO
B25: FINANCIAMENTO COM PARCELAS FIXAS
B26: Número de meses | D26: =ROUND(NPER(D27,D28,-D29),0) -> 67
B27: Taxa de Juros Mensal IN 28 INSS | D27: 0.0197
B28: Valor da Prestação | D28: ='DADOS PARA PETIÇÃO INICIAL'!I21 -> 1221.35
B29: Valor Financiado | D29: ='DADOS PARA PETIÇÃO INICIAL'!J14 -> 45318.44
F30: V. COBRADO
B31: TAXA DA IN 28 REDUZ A PARCELA | F31: =D7 -> 1221.35
B32: FINANCIAMENTO COM PARCELAS FIXAS | F32: TX CONTRAT
B33: Número de meses | D33: ='DADOS PARA PETIÇÃO INICIAL'!I20 -> 72 | F33: =D35 -> 1183.2065
B34: Taxa de Juros Mensal IN 28 INSS | D34: 0.0197 | F34: DIFERENÇA
B35: Valor da Prestação | D35: =-PMT(D34,D33,D36) -> 1183.2065 | F35: =F31-F33 -> 38.143456
B36: Valor Financiado | D36: ='DADOS PARA PETIÇÃO INICIAL'!J14 -> 45318.44
B39: TAXA MEDIA DE MERCADO - REDUZ O PRAZO
B40: FINANCIAMENTO COM PARCELAS FIXAS
B41: Número de meses | D41: =ROUND(NPER(D42,D43,-D44),0) -> 58
B42: Taxa de Juros Mensal | D42: ='DADOS PARA PETIÇÃO INICIAL'!I39 -> 0.0164
B43: Valor da Prestação | D43: ='DADOS PARA PETIÇÃO INICIAL'!I21 -> 1221.35
B44: Valor Financiado | D44: ='DADOS PARA PETIÇÃO INICIAL'!J14 -> 45318.44
B46: TAXA MEDIA DE MERCADO - REDUZ O VALOR DA PARCELA | F46: V. COBRADO
B47: FINANCIAMENTO COM PARCELAS FIXAS | F47: =D43 -> 1221.35
B48: Número de meses | D48: ='DADOS PARA PETIÇÃO INICIAL'!I20 -> 72 | F48: TX CONTRAT
...

Sheet Planilha1

Sheet Planilha2

Sheet INDICES BACARIOS APURAR TX MEDI
B1: HISTORICO DA TAXA DE JUROS - TAXA MÉDIA
B2: Seguimento: | D2: Pessoa Fisica
B3: Período: | D3: ='DADOS PARA PETIÇÃO INICIAL'!F6 -> 45148 | E3: a | G3: ='DADOS PARA PETIÇÃO INICIAL'!I6 -> 0
B4: Modalidade: | D4: Credito pessoal consignado INSS - Pre-Fixado
B5: POSIÇÃO | C5: CNPJ | D5: INSTITUÇÃO FINANCEIRO | F5: % A.M | G5: % A.A.
B7: 1 | C7: 416968 | D7: BANCO INTER | F7: 1.59 | G7: 20.89
B8: 2 | C8: 4902979 | D8: BCO DA AMAZONIA S.A. | F8: 1.64 | G8: 21.55
B9: 3 | C9: 92764489 | D9: BOC BRASIL FINANCEIRA | F9: 1.65 | G9: 21.74
B10: 4 | C10: 92702067 | D10: BCO DO ESTADO DO RS S.A. | F10: 1.66 | G10: 21.82
B11: 5 | C11: 17167412 | D11: FINANCEIRA ALFA S.A. - SCFI | F11: 1.69 | G11: 22.25
B12: 6 | C12: 208 | D12: BRB - BCO DE BRASILIA S.A. | F12: 1.72 | G12: 22.7
B13: 7 | C13: 2038232 | D13: BANCO SICOOB S.A. | F13: 1.77 | G13: 23.36
B14: 8 | C14: 62232889 | D14: BCO DAYCOVAL S.A | F14: 1.79 | G14: 23.75
B15: 9 | C15: 54403563 | D15: BCO ARBI S.A. | F15: 1.81 | G15: 24.08
B16: 10 | C16: 360305 | D16: CAIXA ECONOMICA FEDERAL | F16: 1.82 | G16: 24.15
B17: 11 | C17: 7207996 | D17: BCO BRADESCO FINANC. S.A. | F17: 1.82 | G17: 24.16
B18: 12 | C18: 58160789 | D18: BCO SAFRA S.A. | F18: 1.83 | G18: 24.35
... B43: 37 | C43: 5192316 | D43: VIA CERTA FINANCIADORA S.A. - CFI | F43: 2.12 | G43: 28.61
F44: 0.0164

Sheet 1.1.1 QUITAÇÃO PELA TAXA MEDIA
B1: TAXA DE JUROS COBRADOS - TAXA MEDIA MERCADO
B2: CONTRATO NUMERO: | D2: ='DADOS PARA PETIÇÃO INICIAL'!#REF! -> #REF!
B3: DATA ASSINATURA | C3: TAXA CONTRATUAL | D3: TAXA MEDIA MERCADO | E3: TAXA JUROS PRATICADAS | F3: QUITADO NA PARCELA
B4: ='DADOS PARA PETIÇÃO INICIAL'!I11 -> 45148 | C4: ='DADOS PARA PETIÇÃO INICIAL'!I22 -> 0.0197 | D4: ='DADOS PARA PETIÇÃO INICIAL'!I39 -> 0.0164 | E4: ='DADOS PARA PETIÇÃO INICIAL'!I24 -> 0.020851286 | F4: ='DADOS PARA PETIÇÃO INICIAL'!I43 -> 58
B5: 1ª PARCELA | C5: TOTAL PARCELAS CONTRATADAS | D5: VAL. PARCELA CONTRATUAL | E5: VALOR PARCELA TAXA MEDIA | F5: TOTAL PARCELAS PAGAS
B6: ='DADOS PARA PETIÇÃO INICIAL'!I23 -> 45208 | C6: ='DADOS PARA PETIÇÃO INICIAL'!I14 -> 0 | D6: ='DADOS PARA PETIÇÃO INICIAL'!I21 -> 1221.35 | E6: ='DADOS PARA PETIÇÃO INICIAL'!I40 -> 1077.115 | F6: ='DADOS PARA PETIÇÃO INICIAL'!I28 -> 36
B7: PARCELAS: | C7: MESES | D7: VALOR DA PARCELA | E7: VALOR PELA TAXA MEDIA | F7: DIFERENÇA
B8: 1 | C8: 43412 | D8: 1221.35 | E8: PARCELA QUITADA
B9: 2 | C9: 43442 | D9: 1221.35 | E9: PARCELA QUITADA
B10: 3 | C10: 43473 | D10: 1221.35 | E10: PARCELA QUITADA
B11: 4 | C11: 43504 | D11: 1221.35 | E11: PARCELA QUITADA
B12: 5 | C12: 43532 | D12: 1221.35 | E12: PARCELA QUITADA
B13: 6 | C13: 43563 | D13: 1221.35 | E13: PARCELA QUITADA
B14: 7 | C14: 43593 | D14: 1221.35 | E14: PARCELA QUITADA
B15: 8 | C15: 43624 | D15: 1221.35 | E15: PARCELA QUITADA
B16: 9 | C16: 43654 | D16: 1221.35 | E16: PARCELA QUITADA
B17: 10 | C17: 43685 | D17: 1221.35 | E17: PARCELA QUITADA
B18: 11 | C18: 43716 | D18: 1221.35 | E18: PARCELA QUITADA
B19: 12 | C19: 43746 | D19: 1221.35 | E19: PARCELA QUITADA
... B65: 58 | C65: 45146 | D65: 1221.35 | E65: PARCELA QUITADA
C66: QUITOU NA PARCELA 58ª
B67: 59 | C67: 45177 | D67: 1221.35 | E67: COBRANDA INDEVIDAMENTE
B68: 60 | C68: 45207 | D68: 1221.35 | E68: COBRANDA INDEVIDAMENTE
B69: 61 | C69: 45238 | D69: 1221.35 | E69: COBRANDA INDEVIDAMENTE
B70: 62 | C70: 45268 | D70: 1221.35 | E70: COBRANDA INDEVIDAMENTE
B71: 63 | C71: 45299 | D71: 1221.35 | E71: COBRANDA INDEVIDAMENTE
B72: 64 | C72: 45330 | D72: 1221.35 | E72: COBRANDA INDEVIDAMENTE
B73: 65 | C73: 45359 | D73: 1221.35 | E73: COBRANDA INDEVIDAMENTE
B74: 66 | C74: 45390 | D74: 1221.35 | E74: COBRANDA INDEVIDAMENTE
B75: 67 | C75: 45420 | D75: 1221.35 | E75: COBRANDA INDEVIDAMENTE
B76: 68 | C76: 45451 | D76: 1221.35 | E76: COBRANDA INDEVIDAMENTE
B77: 69 | C77: 45481 | D77: 1221.35 | E77: COBRANDA INDEVIDAMENTE
B78: 70 | C78: 45512 | D78: 1221.35 | E78: COBRANDA INDEVIDAMENTE
... B80: 72 | C80: 45573 | D80: 1221.35 | E80: COBRANDA INDEVIDAMENTE
B81: TOTAL DO INDEBITO | D81: =SUM(D67:D80) -> 17098.9
B82: TOTAL INDEBITO EM DOBRO | D82: =D81*2 -> 34197.8

Sheet 1.1.1 PERCENTUAL TAXA MEDIA
B2: TAXA DE JUROS
B3: Taxa Media de Mercado | C3: ='DADOS PARA PETIÇÃO INICIAL'!I39 -> 0.0164
B4: Taxa Cobrada pelo Banco | C4: ='DADOS PARA PETIÇÃO INICIAL'!I22 -> 0.0197
B5: Porcentagem Acima da Taxa Media | C5: =((C4-C3)/C3) -> 0.20121951
B61: Porcentagem Acima da Taxa Média | C61: =C5 -> 0.20121951
C62: =1-C61 -> 0.79878049

Sheet 2.2.2 QUITAÇÃO PELA IN  28 INSS
B1: TAXA DE JUROS COBRADOS:
B2: CONTRATO NUMERO: | D2: ='DADOS PARA PETIÇÃO INICIAL'!#REF! -> #REF!
B3: DATA ASSINATURA | C3: TAXA CONTRATUAL | D3: TAXA MEDIA MERCADO | E3: TAXA JUROS PRATICADAS | F3: QUITADO NA PARCELA
B4: ='DADOS PARA PETIÇÃO INICIAL'!F6 -> 45148 | C4: ='DADOS PARA PETIÇÃO INICIAL'!I22 -> 0.0197 | D4: ='DADOS PARA PETIÇÃO INICIAL'!I39 -> 0.0164 | E4: ='DADOS PARA PETIÇÃO INICIAL'!I24 -> 0.020851286 | F4: ='DADOS PARA PETIÇÃO INICIAL'!I53 -> 67
B5: 1ª PARCELA | C5: TOTAL PARCELAS CONTRATADAS | D5: VAL. PARCELA CONTRATUAL | E5: VALOR PARCELA TAXA IN 28 | F5: TOTAL PARCELAS PAGAS
B6: ='DADOS PARA PETIÇÃO INICIAL'!I23 -> 45208 | C6: ='DADOS PARA PETIÇÃO INICIAL'!I20 -> 72 | D6: ='DADOS PARA PETIÇÃO INICIAL'!I21 -> 1221.35 | E6: ='TODOS 6 CALCULOS'!D35 -> 1183.2065 | F6: ='DADOS PARA PETIÇÃO INICIAL'!I28 -> 36
B7: PARCELAS: | C7: MESES | D7: VALOR DA PARCELA | E7: VALOR PELA TAXA MEDIA | F7: DIFERENÇA
B8: 1 | C8: 45208 | D8: 1221.35 | E8: PARCELA QUITADA
B9: 2 | C9: 45239 | D9: 1221.35 | E9: PARCELA QUITADA
B10: 3 | C10: 45269 | D10: 1221.35 | E10: PARCELA QUITADA
B11: 4 | C11: 45300 | D11: 1221.35 | E11: PARCELA QUITADA
B12: 5 | C12: 45331 | D12: 1221.35 | E12: PARCELA QUITADA
B13: 6 | C13: 45360 | D13: 1221.35 | E13: PARCELA QUITADA
B14: 7 | C14: 45391 | D14: 1221.35 | E14: PARCELA QUITADA
B15: 8 | C15: 45421 | D15: 1221.35 | E15: PARCELA QUITADA
B16: 9 | C16: 45452 | D16: 1221.35 | E16: PARCELA QUITADA
B17: 10 | C17: 45482 | D17: 1221.35 | E17: PARCELA QUITADA
B18: 11 | C18: 45513 | D18: 1221.35 | E18: PARCELA QUITADA
B19: 12 | C19: 45544 | D19: 1221.35 | E19: PARCELA QUITADA
... B74: 67 | C74: 47217 | D74: 1221.35 | E74: PARCELA QUITADA
C75: QUITOU NA PARCELA 62ª
B76: 68 | C76: 47247 | D76: 1224.35 | E76: COBRANDA INDEVIDAMENTE
B77: 69 | C77: 47278 | D77: 1224.35 | E77: COBRANDA INDEVIDAMENTE
B78: 70 | C78: 47308 | D78: 1224.35 | E78: COBRANDA INDEVIDAMENTE
B79: 71 | C79: 47339 | D79: 1224.35 | E79: COBRANDA INDEVIDAMENTE
B80: 72 | C80: 47370 | D80: 1224.35 | E80: COBRANDA INDEVIDAMENTE
B81: TOTAL DO INDEBITO | D81: =SUM(D76:D80) -> 6121.75
B82: TOTAL INDEBITO EM DOBRO | D82: =D81*2 -> 12243.5

Sheet 2.2.2 PERCENTUAL IN 28
B2: TAXA DE JUROS
B3: Taxa da Instrução Nomativa | C3: ='DADOS PARA PETIÇÃO INICIAL'!I49 -> 0.0197
B4: Taxa Cobrada pelo Banco | C4: ='DADOS PARA PETIÇÃO INICIAL'!I24 -> 0.020851286
B5: Porcentagem Acima da Taxa da IN 28 | C5: =((C4-C3)/C3) -> 0.058440923
B61: Porcentagem Acima da Taxa Média | C61: =C5 -> 0.058440923
C62: =1-C61 -> 0.94155908

Sheet 3.3.3 QUITAÇÃO TAXA CONTRATUAL
B1: TAXA DE JUROS COBRADOS:
B2: CONTRATO NUMERO: | D2: ='DADOS PARA PETIÇÃO INICIAL'!#REF! -> #REF!
B3: DATA ASSINATURA | C3: TAXA CONTRATUAL | D3: TAXA MEDIA MERCADO | E3: TAXA JUROS PRATICADAS | F3: QUITADO NA PARCELA
B4: ='DADOS PARA PETIÇÃO INICIAL'!I11 -> 45148 | C4: ='DADOS PARA PETIÇÃO INICIAL'!I22 -> 0.0197 | D4: ='DADOS PARA PETIÇÃO INICIAL'!I39 -> 0.0164 | E4: ='DADOS PARA PETIÇÃO INICIAL'!I24 -> 0.020851286 | F4: ='DADOS PARA PETIÇÃO INICIAL'!I29 -> 67
B5: 1ª PARCELA | C5: TOTAL PARCELAS CONTRATADAS | D5: VAL. PARCELA COBRADA | E5: VALOR PARCELA TAXA CONTRATO | F5: TOTAL PARCELAS PAGAS
B6: ='DADOS PARA PETIÇÃO INICIAL'!I19 -> 45524.57 | C6: ='DADOS PARA PETIÇÃO INICIAL'!I20 -> 72 | D6: ='DADOS PARA PETIÇÃO INICIAL'!I21 -> 1221.35 | E6: ='DADOS PARA PETIÇÃO INICIAL'!I25 -> 1183.2065 | F6: ='DADOS PARA PETIÇÃO INICIAL'!I20 -> 72
B7: PARCELAS: | C7: MESES | D7: VALOR DA PARCELA | E7: VALOR PELA TAXA MEDIA | F7: DIFERENÇA
B8: 1 | C8: 43412 | D8: 1221.35 | E8: PARCELA QUITADA
B9: 2 | C9: 43442 | D9: 1221.35 | E9: PARCELA QUITADA
B10: 3 | C10: 43473 | D10: 1221.35 | E10: PARCELA QUITADA
B11: 4 | C11: 43504 | D11: 1221.35 | E11: PARCELA QUITADA
B12: 5 | C12: 43532 | D12: 1221.35 | E12: PARCELA QUITADA
B13: 6 | C13: 43563 | D13: 1221.35 | E13: PARCELA QUITADA
B14: 7 | C14: 43593 | D14: 1221.35 | E14: PARCELA QUITADA
B15: 8 | C15: 43624 | D15: 1221.35 | E15: PARCELA QUITADA
B16: 9 | C16: 43654 | D16: 1221.35 | E16: PARCELA QUITADA
B17: 10 | C17: 43685 | D17: 1221.35 | E17: PARCELA QUITADA
B18: 11 | C18: 43716 | D18: 1221.35 | E18: PARCELA QUITADA
B19: 12 | C19: 43746 | D19: 1221.35 | E19: PARCELA QUITADA
... B74: 67 | C74: 45420 | D74: 1221.35 | E74: PARCELA QUITADA
C75: QUITOU NA PARCELA 67ª
B76: 68 | C76: 46181 | D76: 1221.35 | E76: COBRANDA INDEVIDAMENTE
B77: 69 | C77: 46211 | D77: 1221.35 | E77: COBRANDA INDEVIDAMENTE
B78: 70 | C78: 46242 | D78: 1221.35 | E78: COBRANDA INDEVIDAMENTE
B79: 71 | C79: 46273 | D79: 1221.35 | E79: COBRANDA INDEVIDAMENTE
B80: 72 | C80: 46303 | D80: 1221.35 | E80: COBRANDA INDEVIDAMENTE
B81: TOTAL DO INDEBITO | D81: =SUM(D76:D80) -> 6106.75
B82: TOTAL INDEBITO EM DOBRO | D82: =D81*2 -> 12213.5

Sheet 3.3.3 PERCENTUAL CONTRATO
B2: TAXA DE JUROS
B3: Taxa Contratual | C3: ='DADOS PARA PETIÇÃO INICIAL'!I22 -> 0.0197
B4: Taxa Cobrada pelo Banco | C4: ='DADOS PARA PETIÇÃO INICIAL'!I24 -> 0.020851286
B5: Porcentagem Acima da Taxa Pactuada | C5: =((C4-C3)/C3) -> 0.058440923
B61: Porcentagem Acima da Taxa Média | C61: =C5 -> 0.058440923
C62: =1-C61 -> 0.94155908
